<?xml version="1.0" encoding="utf-8"?>
<!-- Created by Yasen Jia (https://github.com/lupinjia, jason_1120202397@163.com)-->
<robot name="walker3d_hip3d">
  <material name="yellow">
      <color rgba="0.8 0.6 0.4 1.0"/>
  </material>
  <material name="purple">
    <color rgba="0.7 0.3 0.6 1"/>
  </material>
  <link name="torso">
    <inertial>
      <origin
        xyz="0 0 0.35"
        rpy="0 0 0" />
      <mass
        value="53.5" />
      <inertia
        ixx="2.5"
        ixy="0.0"
        ixz="0.0"
        iyy="4.0"
        iyz="0.0"
        izz="1.5" />
    </inertial>
    <visual>
      <origin
        xyz="0 0 0.35"
        rpy="0 0 0" />
      <geometry>
        <cylinder radius="0.075" length="0.7"/>
      </geometry>
      <material name="yellow">
      </material>
    </visual>
    <collision>
      <origin
        xyz="0 0 0.35"
        rpy="0 0 0" />
      <geometry>
        <cylinder radius="0.075" length="0.7"/>
      </geometry>
    </collision>
  </link>
  <link name="right_hip_dummy1">
  </link>
  <joint 
    name="hip_joint_saggital_right"
    type="revolute">
    <parent link="torso"/>
    <child link="right_hip_dummy1"/>
    <origin
      xyz="0 -0.08 0"
      rpy="0 0 0" />
    <axis
      xyz="0 1 0" />
    <limit
      lower="-0.7854"
      upper="0.7854"
      effort="300"
      velocity="10" />
  </joint>
  <link name="right_hip_dummy2">
  </link>
  <joint 
    name="hip_joint_frontal_right"
    type="revolute">
    <parent link="right_hip_dummy1"/>
    <child link="right_hip_dummy2"/>
    <origin
      xyz="0 0 0"
      rpy="0 0 0" />
    <axis
      xyz="1 0 0" />
    <limit
      lower="-0.8727"
      upper="0.8727"
      effort="300"
      velocity="10" />
  </joint>
  <link name="right_thigh">
    <inertial>
      <origin
        xyz="0 0 -0.2"
        rpy="0 0 0" />
      <mass
        value="8.5" />
      <inertia
        ixx="0.15"
        ixy="0.0"
        ixz="0.0"
        iyy="0.15"
        iyz="0.0"
        izz="0.03" />
    </inertial>
    <visual>
      <origin
        xyz="0 0 -0.25"
        rpy="0 0 0" />
      <geometry>
        <cylinder radius="0.05" length="0.4"/>
      </geometry>
      <material name="yellow">
      </material>
    </visual>
    <collision>
      <origin
        xyz="0 0 -0.25"
        rpy="0 0 0" />
      <geometry>
        <cylinder radius="0.05" length="0.4"/>
      </geometry>
    </collision>
  </link>
  <joint 
    name="hip_joint_transversal_right"
    type="revolute">
    <parent link="right_hip_dummy2"/>
    <child link="right_thigh"/>
    <origin
      xyz="0 0 0"
      rpy="0 0 0" />
    <axis
      xyz="0 0 1" />
    <limit
      lower="-0.26"
      upper="0.26"
      effort="300"
      velocity="10" />
  </joint>
  <link name="right_shank">
    <inertial>
      <origin
        xyz="0 0 -0.2"
        rpy="0 0 0" />
      <mass
        value="3.5" />
      <inertia
        ixx="0.05"
        ixy="0.0"
        ixz="0.0"
        iyy="0.05"
        iyz="0.0"
        izz="0.003" />
    </inertial>
    <visual>
      <origin
        xyz="0 0 -0.25"
        rpy="0 0 0" />
      <geometry>
        <cylinder radius="0.04" length="0.4"/>
      </geometry>
      <material name="yellow">
      </material>
    </visual>
    <collision>
      <origin
        xyz="0 0 -0.25"
        rpy="0 0 0" />
      <geometry>
        <cylinder radius="0.04" length="0.4"/>
      </geometry>
    </collision>
  </link>
  <joint 
    name="knee_joint_right"
    type="revolute">
    <parent link="right_thigh"/>
    <child link="right_shank"/>
    <origin
      xyz="0 0 -0.5"
      rpy="0 0 0" />
    <axis
      xyz="0 1 0" />
    <limit
      lower="0"
      upper="2.6180"
      effort="300"
      velocity="10" />
  </joint>
  <link name="right_foot">
    <inertial>
      <origin
        xyz="0.06 0 -0.07"
        rpy="0 0 0" />
      <mass
        value="1.5" />
      <inertia
        ixx="0.003"
        ixy="0.0"
        ixz="0.0"
        iyy="0.006"
        iyz="0.0"
        izz="0.005" />
    </inertial>
    <visual>
      <origin
        xyz="0.0675 -0.005 -0.04"
        rpy="0 0 0" />
      <geometry>
        <box size="0.22 0.1 0.08"/>
      </geometry>
      <material name="yellow">
      </material>
    </visual>
    <collision>
      <origin
        xyz="0.0675 -0.005 -0.04"
        rpy="0 0 0" />
      <geometry>
        <box size="0.22 0.1 0.08"/>
      </geometry>
    </collision>
  </link>
  <joint 
    name="ankle_joint_right"
    type="revolute">
    <parent link="right_shank"/>
    <child link="right_foot"/>
    <origin
      xyz="0 0 -0.5"
      rpy="0 0 0" />
    <axis
      xyz="0 1 0" />
    <limit
      lower="-0.5"
      upper="0.6981"
      effort="300"
      velocity="10" />
  </joint>
  <!-- Left leg -->
  <link name="left_hip_dummy1">
  </link>
  <joint 
    name="hip_joint_saggital_left"
    type="revolute">
    <parent link="torso"/>
    <child link="left_hip_dummy1"/>
    <origin
      xyz="0 0.08 0"
      rpy="0 0 0" />
    <axis
      xyz="0 1 0" />
    <limit
      lower="-0.7854"
      upper="0.7854"
      effort="300"
      velocity="10" />
  </joint>
  <link name="left_hip_dummy2">
  </link>
  <joint 
    name="hip_joint_frontal_left"
    type="revolute">
    <parent link="left_hip_dummy1"/>
    <child link="left_hip_dummy2"/>
    <origin
      xyz="0 0 0"
      rpy="0 0 0" />
    <axis
      xyz="1 0 0" />
    <limit
      lower="-0.8727"
      upper="0.8727"
      effort="300"
      velocity="10" />
  </joint>
  <link name="left_thigh">
    <inertial>
      <origin
        xyz="0 0 -0.2"
        rpy="0 0 0" />
      <mass
        value="8.5" />
      <inertia
        ixx="0.15"
        ixy="0.0"
        ixz="0.0"
        iyy="0.15"
        iyz="0.0"
        izz="0.03" />
    </inertial>
    <visual>
      <origin
        xyz="0 0 -0.25"
        rpy="0 0 0" />
      <geometry>
        <cylinder radius="0.05" length="0.4"/>
      </geometry>
      <material name="purple">
      </material>
    </visual>
    <collision>
      <origin
        xyz="0 0 -0.25"
        rpy="0 0 0" />
      <geometry>
        <cylinder radius="0.05" length="0.4"/>
      </geometry>
    </collision>
  </link>
  <joint 
    name="hip_joint_transversal_left"
    type="revolute">
    <parent link="left_hip_dummy2"/>
    <child link="left_thigh"/>
    <origin
      xyz="0 0 0"
      rpy="0 0 0" />
    <axis
      xyz="0 0 1" />
    <limit
      lower="-0.26"
      upper="0.26"
      effort="300"
      velocity="10" />
  </joint>
  <link name="left_shank">
    <inertial>
      <origin
        xyz="0 0 -0.2"
        rpy="0 0 0" />
      <mass
        value="3.5" />
      <inertia
        ixx="0.05"
        ixy="0.0"
        ixz="0.0"
        iyy="0.05"
        iyz="0.0"
        izz="0.003" />
    </inertial>
    <visual>
      <origin
        xyz="0 0 -0.25"
        rpy="0 0 0" />
      <geometry>
        <cylinder radius="0.04" length="0.4"/>
      </geometry>
      <material name="purple">
      </material>
    </visual>
    <collision>
      <origin
        xyz="0 0 -0.25"
        rpy="0 0 0" />
      <geometry>
        <cylinder radius="0.04" length="0.4"/>
      </geometry>
    </collision>
  </link>
  <joint 
    name="knee_joint_left"
    type="revolute">
    <parent link="left_thigh"/>
    <child link="left_shank"/>
    <origin
      xyz="0 0 -0.5"
      rpy="0 0 0" />
    <axis
      xyz="0 1 0" />
    <limit
      lower="0"
      upper="2.6180"
      effort="300"
      velocity="10" />
  </joint>
  <link name="left_foot">
    <inertial>
      <origin
        xyz="0.06 0 -0.07"
        rpy="0 0 0" />
      <mass
        value="1.5" />
      <inertia
        ixx="0.003"
        ixy="0.0"
        ixz="0.0"
        iyy="0.006"
        iyz="0.0"
        izz="0.005" />
    </inertial>
    <visual>
      <origin
        xyz="0.0675 -0.005 -0.04"
        rpy="0 0 0" />
      <geometry>
        <box size="0.22 0.1 0.08"/>
      </geometry>
      <material name="purple">
      </material>
    </visual>
    <collision>
      <origin
        xyz="0.0675 -0.005 -0.04"
        rpy="0 0 0" />
      <geometry>
        <box size="0.22 0.1 0.08"/>
      </geometry>
    </collision>
  </link>
  <joint 
    name="ankle_joint_left"
    type="revolute">
    <parent link="left_shank"/>
    <child link="left_foot"/>
    <origin
      xyz="0 0 -0.5"
      rpy="0 0 0" />
    <axis
      xyz="0 1 0" />
    <limit
      lower="-0.5"
      upper="0.6981"
      effort="300"
      velocity="10" />
  </joint>
</robot>